Workbook

Sheet Resumo
B1: Testes de GPU no SageMaker
B2: Batch Transform e Async Inference · g6, g5 e p5e · com e sem fracionamento de GPU
B4: Comparar no teste ▸ | C4: 1M | E4: clique e escolha: 1 req./arquivo · Lote 40 · 1M · Rodada longa · 8 req. em voo
B6: CENÁRIO | D6: VELOCIDADE | H6: CONFIABILIDADE | J6: CUSTO | M6: USO DA MÁQUINA
B7: Instância | C7: Fracionamento | D7: Linhas por segundo | E7: vs g6 sem fracionamento | F7: Tempo do teste | G7: Tempo p/ 24M | H7: Requisições / arquivos ok | I7: Falhas | J7: Custo do teste (USD) | K7: Custo por 1M (USD) | L7: Custo p/ 24M (USD) | M7: GPU usada | N7: Memória de GPU | O7: Tempo do modelo por req. (s) | P7: Leitura
B8: Batch Transform
B9: ="g6.12xlarge "&INDEX(Instancias!$C$2:$C$4,MATCH("ml.g6.12xlarge",Instancias!$A$2:$A$4,0))&"× "&SUBSTITUTE(INDEX(Instancias!$B$2:$B$4,MATCH("ml.g6.12xlarge",Instancias!$A$2:$A$4,0)),"NVIDIA ","")&" · "&INDEX(Instancias!$E$2:$E$4,MATCH("ml.g6.12xlarge",Instancias!$A$2:$A$4,0))&" GB GPU · "&INDEX(Instancias!$F$2:$F$4,MATCH("ml.g6.12xlarge",Instancias!$A$2:$A$4,0))&" vCPU · "&INDEX(Instancias!$G$2:$G$4,MATCH("ml.g6.12xlarge",Instancias!$A$2:$A$4,0))&" GiB" -> g6.12xlarge 4× L4 · 96 GB GPU · 48 vCPU · 192 GiB | C9: sem | D9: =IF(COUNTIFS(Testes[Serviço],"Batch",Testes[Instância],"ml.g6.12xlarge",Testes[Fracionamento],"Não",Testes[Teste],$C$4)=0,"",IFERROR(AVERAGEIFS(Testes[Throughput processamento (linhas/s)],Testes[Serviço],"Batch",Testes[Instância],"ml.g6.12xlarge",Testes[Fracionamento],"Não",Testes[Teste],$C$4),"")) -> 176 | E9: =IF(OR(NOT(ISNUMBER(D9)),NOT(ISNUMBER(D9))),"",IF(ROW()=9,"base",D9/D9-1)) -> base | F9: =IF(COUNTIFS(Testes[Serviço],"Batch",Testes[Instância],"ml.g6.12xlarge",Testes[Fracionamento],"Não",Testes[Teste],$C$4)=0,"",IFERROR(AVERAGEIFS(Testes[Tempo total (min)],Testes[Serviço],"Batch",Testes[Instância],"ml.g6.12xlarge",Testes[Fracionamento],"Não",Testes[Teste],$C$4)/1440,"")) -> 0.06875 | G9: =IF(ISNUMBER(D9),24000000/D9/86400,"") -> 1.5782828 | H9: =IF(COUNTIFS(Testes[Serviço],"Batch",Testes[Instância],"ml.g6.12xlarge",Testes[Fracionamento],"Não",Testes[Teste],$C$4)=0,"",IFERROR(AVERAGEIFS(Testes[% ok],Testes[Serviço],"Batch",Testes[Instância],"ml.g6.12xlarge",Testes[Fracionamento],"Não",Testes[Teste],$C$4),"")) -> 1 | I9: =IF(COUNTIFS(Testes[Serviço],"Batch",Testes[Instância],"ml.g6.12xlarge",Testes[Fracionamento],"Não",Testes[Teste],$C$4)=0,"",SUMIFS(Testes[Falhas],Testes[Serviço],"Batch",Testes[Instância],"ml.g6.12xlarge",Testes[Fracionamento],"Não",Testes[Teste],$C$4)) -> 0 | J9: =IF(COUNTIFS(Testes[Serviço],"Batch",Testes[Instância],"ml.g6.12xlarge",Testes[Fracionamento],"Não",Testes[Teste],$C$4)=0,"",IFERROR(AVERAGEIFS(Testes[Custo (USD)],Testes[Serviço],"Batch",Testes[Instância],"ml.g6.12xlarge",Testes[Fracionamento],"Não",Testes[Teste],$C$4),"")) -> 8.63 | K9: =IF(COUNTIFS(Testes[Serviço],"Batch",Testes[Instância],"ml.g6.12xlarge",Testes[Fracionamento],"Não",Testes[Teste],$C$4)=0,"",IFERROR(AVERAGEIFS(Testes[Custo por 1M linhas (USD)],Testes[Serviço],"Batch",Testes[Instância],"ml.g6.12xlarge",Testes[Fracionamento],"Não",Testes[Teste],$C$4),"")) -> 9.0539703 | L9: =IF(ISNUMBER(K9),K9*24,"") -> 217.29529 | M9: =IF(COUNTIFS(Testes[Serviço],"Batch",Testes[Instância],"ml.g6.12xlarge",Testes[Fracionamento],"Não",Testes[Teste],$C$4)=0,"",IFERROR(AVERAGEIFS(Testes[GPU média /GPU],Testes[Serviço],"Batch",Testes[Instância],"ml.g6.12xlarge",Testes[Fracionamento],"Não",Testes[Teste],$C$4),"")) -> 0.9575 | N9: =IF(COUNTIFS(Testes[Serviço],"Batch",Testes[Instância],"ml.g6.12xlarge",Testes[Fracionamento],"Não",Testes[Teste],$C$4)=0,"",IFERROR(AVERAGEIFS(Testes[Mem. GPU média /GPU],Testes[Serviço],"Batch",Testes[Instância],"ml.g6.12xlarge",Testes[Fracionamento],"Não",Testes[Teste],$C$4),"")) -> 0.137 | O9: =IF(COUNTIFS(Testes[Serviço],"Batch",Testes[Instância],"ml.g6.12xlarge",Testes[Fracionamento],"Não",Testes[Teste],$C$4)=0,"",IFERROR(AVERAGEIFS(Testes[ModelLatency (s)],Testes[Serviço],"Batch",Testes[Instância],"ml.g6.12xlarge",Testes[Fracionamento],"Não",Testes[Teste],$C$4),"")) | P9: =IF(NOT(ISNUMBER(D9)),"não testado",IF(ROW()=9,"referência"&IF(I9>0," · "&I9&" falha(s)",""),IF(E9>=1,TEXT(1+E9,"0")&"× mais rápida",IF(E9>=0.1,"mais rápida ("&TEXT(E9,"+0%")&")",IF(E9<=-0.05,"mais lenta ("&TEXT(E9,"0%")&")","parecida ("&TEXT(E9,"+0%;-0%")&")")))&IF(N(H9)<0.95," · só "&TEXT(H9,"0%")&" ok",IF(I9>0," · "&I9&" falha(s)","")))) -> referência | S9: Batch · g6.12xl
B10: ="g6.12xlarge "&INDEX(Instancias!$C$2:$C$4,MATCH("ml.g6.12xlarge",Instancias!$A$2:$A$4,0))&"× "&SUBSTITUTE(INDEX(Instancias!$B$2:$B$4,MATCH("ml.g6.12xlarge",Instancias!$A$2:$A$4,0)),"NVIDIA ","")&" · "&INDEX(Instancias!$E$2:$E$4,MATCH("ml.g6.12xlarge",Instancias!$A$2:$A$4,0))&" GB GPU · "&INDEX(Instancias!$F$2:$F$4,MATCH("ml.g6.12xlarge",Instancias!$A$2:$A$4,0))&" vCPU · "&INDEX(Instancias!$G$2:$G$4,MATCH("ml.g6.12xlarge",Instancias!$A$2:$A$4,0))&" GiB" -> g6.12xlarge 4× L4 · 96 GB GPU · 48 vCPU · 192 GiB | C10: com 0,5 GPU | D10: =IF(COUNTIFS(Testes[Serviço],"Batch",Testes[Instância],"ml.g6.12xlarge",Testes[Fracionamento],"Sim",Testes[Teste],$C$4)=0,"",IFERROR(AVERAGEIFS(Testes[Throughput processamento (linhas/s)],Testes[Serviço],"Batch",Testes[Instância],"ml.g6.12xlarge",Testes[Fracionamento],"Sim",Testes[Teste],$C$4),"")) | E10: =IF(OR(NOT(ISNUMBER(D10)),NOT(ISNUMBER(D9))),"",IF(ROW()=9,"base",D10/D9-1)) | F10: =IF(COUNTIFS(Testes[Serviço],"Batch",Testes[Instância],"ml.g6.12xlarge",Testes[Fracionamento],"Sim",Testes[Teste],$C$4)=0,"",IFERROR(AVERAGEIFS(Testes[Tempo total (min)],Testes[Serviço],"Batch",Testes[Instância],"ml.g6.12xlarge",Testes[Fracionamento],"Sim",Testes[Teste],$C$4)/1440,"")) | G10: =IF(ISNUMBER(D10),24000000/D10/86400,"") | H10: =IF(COUNTIFS(Testes[Serviço],"Batch",Testes[Instância],"ml.g6.12xlarge",Testes[Fracionamento],"Sim",Testes[Teste],$C$4)=0,"",IFERROR(AVERAGEIFS(Testes[% ok],Testes[Serviço],"Batch",Testes[Instância],"ml.g6.12xlarge",Testes[Fracionamento],"Sim",Testes[Teste],$C$4),"")) | I10: =IF(COUNTIFS(Testes[Serviço],"Batch",Testes[Instância],"ml.g6.12xlarge",Testes[Fracionamento],"Sim",Testes[Teste],$C$4)=0,"",SUMIFS(Testes[Falhas],Testes[Serviço],"Batch",Testes[Instância],"ml.g6.12xlarge",Testes[Fracionamento],"Sim",Testes[Teste],$C$4)) | J10: =IF(COUNTIFS(Testes[Serviço],"Batch",Testes[Instância],"ml.g6.12xlarge",Testes[Fracionamento],"Sim",Testes[Teste],$C$4)=0,"",IFERROR(AVERAGEIFS(Testes[Custo (USD)],Testes[Serviço],"Batch",Testes[Instância],"ml.g6.12xlarge",Testes[Fracionamento],"Sim",Testes[Teste],$C$4),"")) | K10: =IF(COUNTIFS(Testes[Serviço],"Batch",Testes[Instância],"ml.g6.12xlarge",Testes[Fracionamento],"Sim",Testes[Teste],$C$4)=0,"",IFERROR(AVERAGEIFS(Testes[Custo por 1M linhas (USD)],Testes[Serviço],"Batch",Testes[Instância],"ml.g6.12xlarge",Testes[Fracionamento],"Sim",Testes[Teste],$C$4),"")) | L10: =IF(ISNUMBER(K10),K10*24,"") | M10: =IF(COUNTIFS(Testes[Serviço],"Batch",Testes[Instância],"ml.g6.12xlarge",Testes[Fracionamento],"Sim",Testes[Teste],$C$4)=0,"",IFERROR(AVERAGEIFS(Testes[GPU média /GPU],Testes[Serviço],"Batch",Testes[Instância],"ml.g6.12xlarge",Testes[Fracionamento],"Sim",Testes[Teste],$C$4),"")) | N10: =IF(COUNTIFS(Testes[Serviço],"Batch",Testes[Instância],"ml.g6.12xlarge",Testes[Fracionamento],"Sim",Testes[Teste],$C$4)=0,"",IFERROR(AVERAGEIFS(Testes[Mem. GPU média /GPU],Testes[Serviço],"Batch",Testes[Instância],"ml.g6.12xlarge",Testes[Fracionamento],"Sim",Testes[Teste],$C$4),"")) | O10: =IF(COUNTIFS(Testes[Serviço],"Batch",Testes[Instância],"ml.g6.12xlarge",Testes[Fracionamento],"Sim",Testes[Teste],$C$4)=0,"",IFERROR(AVERAGEIFS(Testes[ModelLatency (s)],Testes[Serviço],"Batch",Testes[Instância],"ml.g6.12xlarge",Testes[Fracionamento],"Sim",Testes[Teste],$C$4),"")) | P10: =IF(NOT(ISNUMBER(D10)),"não testado",IF(ROW()=9,"referência"&IF(I10>0," · "&I10&" falha(s)",""),IF(E10>=1,TEXT(1+E10,"0")&"× mais rápida",IF(E10>=0.1,"mais rápida ("&TEXT(E10,"+0%")&")",IF(E10<=-0.05,"mais lenta ("&TEXT(E10,"0%")&")","parecida ("&TEXT(E10,"+0%;-0%")&")")))&IF(N(H10)<0.95," · só "&TEXT(H10,"0%")&" ok",IF(I10>0," · "&I10&" falha(s)","")))) -> não testado | S10: Batch · g6.12xl · frac
B11: ="g5.12xlarge "&INDEX(Instancias!$C$2:$C$4,MATCH("ml.g5.12xlarge",Instancias!$A$2:$A$4,0))&"× "&SUBSTITUTE(INDEX(Instancias!$B$2:$B$4,MATCH("ml.g5.12xlarge",Instancias!$A$2:$A$4,0)),"NVIDIA ","")&" · "&INDEX(Instancias!$E$2:$E$4,MATCH("ml.g5.12xlarge",Instancias!$A$2:$A$4,0))&" GB GPU · "&INDEX(Instancias!$F$2:$F$4,MATCH("ml.g5.12xlarge",Instancias!$A$2:$A$4,0))&" vCPU · "&INDEX(Instancias!$G$2:$G$4,MATCH("ml.g5.12xlarge",Instancias!$A$2:$A$4,0))&" GiB" -> g5.12xlarge 4× A10G · 96 GB GPU · 48 vCPU · 192 GiB | C11: sem | D11: =IF(COUNTIFS(Testes[Serviço],"Batch",Testes[Instância],"ml.g5.12xlarge",Testes[Fracionamento],"Não",Testes[Teste],$C$4)=0,"",IFERROR(AVERAGEIFS(Testes[Throughput processamento (linhas/s)],Testes[Serviço],"Batch",Testes[Instância],"ml.g5.12xlarge",Testes[Fracionamento],"Não",Testes[Teste],$C$4),"")) -> 211 | E11: =IF(OR(NOT(ISNUMBER(D11)),NOT(ISNUMBER(D9))),"",IF(ROW()=9,"base",D11/D9-1)) -> 0.19886364 | F11: =IF(COUNTIFS(Testes[Serviço],"Batch",Testes[Instância],"ml.g5.12xlarge",Testes[Fracionamento],"Não",Testes[Teste],$C$4)=0,"",IFERROR(AVERAGEIFS(Testes[Tempo total (min)],Testes[Serviço],"Batch",Testes[Instância],"ml.g5.12xlarge",Testes[Fracionamento],"Não",Testes[Teste],$C$4)/1440,"")) -> 0.057638889 | G11: =IF(ISNUMBER(D11),24000000/D11/86400,"") -> 1.3164824 | H11: =IF(COUNTIFS(Testes[Serviço],"Batch",Testes[Instância],"ml.g5.12xlarge",Testes[Fracionamento],"Não",Testes[Teste],$C$4)=0,"",IFERROR(AVERAGEIFS(Testes[% ok],Testes[Serviço],"Batch",Testes[Instância],"ml.g5.12xlarge",Testes[Fracionamento],"Não",Testes[Teste],$C$4),"")) -> 1 | I11: =IF(COUNTIFS(Testes[Serviço],"Batch",Testes[Instância],"ml.g5.12xlarge",Testes[Fracionamento],"Não",Testes[Teste],$C$4)=0,"",SUMIFS(Testes[Falhas],Testes[Serviço],"Batch",Testes[Instância],"ml.g5.12xlarge",Testes[Fracionamento],"Não",Testes[Teste],$C$4)) -> 0 | J11: =IF(COUNTIFS(Testes[Serviço],"Batch",Testes[Instância],"ml.g5.12xlarge",Testes[Fracionamento],"Não",Testes[Teste],$C$4)=0,"",IFERROR(AVERAGEIFS(Testes[Custo (USD)],Testes[Serviço],"Batch",Testes[Instância],"ml.g5.12xlarge",Testes[Fracionamento],"Não",Testes[Teste],$C$4),"")) -> 8.86 | K11: =IF(COUNTIFS(Testes[Serviço],"Batch",Testes[Instância],"ml.g5.12xlarge",Testes[Fracionamento],"Não",Testes[Teste],$C$4)=0,"",IFERROR(AVERAGEIFS(Testes[Custo por 1M linhas (USD)],Testes[Serviço],"Batch",Testes[Instância],"ml.g5.12xlarge",Testes[Fracionamento],"Não",Testes[Teste],$C$4),"")) -> 9.2952696 | L11: =IF(ISNUMBER(K11),K11*24,"") -> 223.08647 | M11: =IF(COUNTIFS(Testes[Serviço],"Batch",Testes[Instância],"ml.g5.12xlarge",Testes[Fracionamento],"Não",Testes[Teste],$C$4)=0,"",IFERROR(AVERAGEIFS(Testes[GPU média /GPU],Testes[Serviço],"Batch",Testes[Instância],"ml.g5.12xlarge",Testes[Fracionamento],"Não",Testes[Teste],$C$4),"")) -> 0.6925 | N11: =IF(COUNTIFS(Testes[Serviço],"Batch",Testes[Instância],"ml.g5.12xlarge",Testes[Fracionamento],"Não",Testes[Teste],$C$4)=0,"",IFERROR(AVERAGEIFS(Testes[Mem. GPU média /GPU],Testes[Serviço],"Batch",Testes[Instância],"ml.g5.12xlarge",Testes[Fracionamento],"Não",Testes[Teste],$C$4),"")) -> 0.09625 | O11: =IF(COUNTIFS(Testes[Serviço],"Batch",Testes[Instância],"ml.g5.12xlarge",Testes[Fracionamento],"Não",Testes[Teste],$C$4)=0,"",IFERROR(AVERAGEIFS(Testes[ModelLatency (s)],Testes[Serviço],"Batch",Testes[Instância],"ml.g5.12xlarge",Testes[Fracionamento],"Não",Testes[Teste],$C$4),"")) | P11: =IF(NOT(ISNUMBER(D11)),"não testado",IF(ROW()=9,"referência"&IF(I11>0," · "&I11&" falha(s)",""),IF(E11>=1,TEXT(1+E11,"0")&"× mais rápida",IF(E11>=0.1,"mais rápida ("&TEXT(E11,"+0%")&")",IF(E11<=-0.05,"mais lenta ("&TEXT(E11,"0%")&")","parecida ("&TEXT(E11,"+0%;-0%")&")")))&IF(N(H11)<0.95," · só "&TEXT(H11,"0%")&" ok",IF(I11>0," · "&I11&" falha(s)","")))) -> mais rápida (+20%) | S11: Batch · g5.12xl
B12: ="g5.12xlarge "&INDEX(Instancias!$C$2:$C$4,MATCH("ml.g5.12xlarge",Instancias!$A$2:$A$4,0))&"× "&SUBSTITUTE(INDEX(Instancias!$B$2:$B$4,MATCH("ml.g5.12xlarge",Instancias!$A$2:$A$4,0)),"NVIDIA ","")&" · "&INDEX(Instancias!$E$2:$E$4,MATCH("ml.g5.12xlarge",Instancias!$A$2:$A$4,0))&" GB GPU · "&INDEX(Instancias!$F$2:$F$4,MATCH("ml.g5.12xlarge",Instancias!$A$2:$A$4,0))&" vCPU · "&INDEX(Instancias!$G$2:$G$4,MATCH("ml.g5.12xlarge",Instancias!$A$2:$A$4,0))&" GiB" -> g5.12xlarge 4× A10G · 96 GB GPU · 48 vCPU · 192 GiB | C12: com 0,5 GPU | D12: =IF(COUNTIFS(Testes[Serviço],"Batch",Testes[Instância],"ml.g5.12xlarge",Testes[Fracionamento],"Sim",Testes[Teste],$C$4)=0,"",IFERROR(AVERAGEIFS(Testes[Throughput processamento (linhas/s)],Testes[Serviço],"Batch",Testes[Instância],"ml.g5.12xlarge",Testes[Fracionamento],"Sim",Testes[Teste],$C$4),"")) | E12: =IF(OR(NOT(ISNUMBER(D12)),NOT(ISNUMBER(D9))),"",IF(ROW()=9,"base",D12/D9-1)) | F12: =IF(COUNTIFS(Testes[Serviço],"Batch",Testes[Instância],"ml.g5.12xlarge",Testes[Fracionamento],"Sim",Testes[Teste],$C$4)=0,"",IFERROR(AVERAGEIFS(Testes[Tempo total (min)],Testes[Serviço],"Batch",Testes[Instância],"ml.g5.12xlarge",Testes[Fracionamento],"Sim",Testes[Teste],$C$4)/1440,"")) | G12: =IF(ISNUMBER(D12),24000000/D12/86400,"") | H12: =IF(COUNTIFS(Testes[Serviço],"Batch",Testes[Instância],"ml.g5.12xlarge",Testes[Fracionamento],"Sim",Testes[Teste],$C$4)=0,"",IFERROR(AVERAGEIFS(Testes[% ok],Testes[Serviço],"Batch",Testes[Instância],"ml.g5.12xlarge",Testes[Fracionamento],"Sim",Testes[Teste],$C$4),"")) | I12: =IF(COUNTIFS(Testes[Serviço],"Batch",Testes[Instância],"ml.g5.12xlarge",Testes[Fracionamento],"Sim",Testes[Teste],$C$4)=0,"",SUMIFS(Testes[Falhas],Testes[Serviço],"Batch",Testes[Instância],"ml.g5.12xlarge",Testes[Fracionamento],"Sim",Testes[Teste],$C$4)) | J12: =IF(COUNTIFS(Testes[Serviço],"Batch",Testes[Instância],"ml.g5.12xlarge",Testes[Fracionamento],"Sim",Testes[Teste],$C$4)=0,"",IFERROR(AVERAGEIFS(Testes[Custo (USD)],Testes[Serviço],"Batch",Testes[Instância],"ml.g5.12xlarge",Testes[Fracionamento],"Sim",Testes[Teste],$C$4),"")) | K12: =IF(COUNTIFS(Testes[Serviço],"Batch",Testes[Instância],"ml.g5.12xlarge",Testes[Fracionamento],"Sim",Testes[Teste],$C$4)=0,"",IFERROR(AVERAGEIFS(Testes[Custo por 1M linhas (USD)],Testes[Serviço],"Batch",Testes[Instância],"ml.g5.12xlarge",Testes[Fracionamento],"Sim",Testes[Teste],$C$4),"")) | L12: =IF(ISNUMBER(K12),K12*24,"") | M12: =IF(COUNTIFS(Testes[Serviço],"Batch",Testes[Instância],"ml.g5.12xlarge",Testes[Fracionamento],"Sim",Testes[Teste],$C$4)=0,"",IFERROR(AVERAGEIFS(Testes[GPU média /GPU],Testes[Serviço],"Batch",Testes[Instância],"ml.g5.12xlarge",Testes[Fracionamento],"Sim",Testes[Teste],$C$4),"")) | N12: =IF(COUNTIFS(Testes[Serviço],"Batch",Testes[Instância],"ml.g5.12xlarge",Testes[Fracionamento],"Sim",Testes[Teste],$C$4)=0,"",IFERROR(AVERAGEIFS(Testes[Mem. GPU média /GPU],Testes[Serviço],"Batch",Testes[Instância],"ml.g5.12xlarge",Testes[Fracionamento],"Sim",Testes[Teste],$C$4),"")) | O12: =IF(COUNTIFS(Testes[Serviço],"Batch",Testes[Instância],"ml.g5.12xlarge",Testes[Fracionamento],"Sim",Testes[Teste],$C$4)=0,"",IFERROR(AVERAGEIFS(Testes[ModelLatency (s)],Testes[Serviço],"Batch",Testes[Instância],"ml.g5.12xlarge",Testes[Fracionamento],"Sim",Testes[Teste],$C$4),"")) | P12: =IF(NOT(ISNUMBER(D12)),"não testado",IF(ROW()=9,"referência"&IF(I12>0," · "&I12&" falha(s)",""),IF(E12>=1,TEXT(1+E12,"0")&"× mais rápida",IF(E12>=0.1,"mais rápida ("&TEXT(E12,"+0%")&")",IF(E12<=-0.05,"mais lenta ("&TEXT(E12,"0%")&")","parecida ("&TEXT(E12,"+0%;-0%")&")")))&IF(N(H12)<0.95," · só "&TEXT(H12,"0%")&" ok",IF(I12>0," · "&I12&" falha(s)","")))) -> não testado | S12: Batch · g5.12xl · frac
B13: Async Inference
B14: ="g6.12xlarge "&INDEX(Instancias!$C$2:$C$4,MATCH("ml.g6.12xlarge",Instancias!$A$2:$A$4,0))&"× "&SUBSTITUTE(INDEX(Instancias!$B$2:$B$4,MATCH("ml.g6.12xlarge",Instancias!$A$2:$A$4,0)),"NVIDIA ","")&" · "&INDEX(Instancias!$E$2:$E$4,MATCH("ml.g6.12xlarge",Instancias!$A$2:$A$4,0))&" GB GPU · "&INDEX(Instancias!$F$2:$F$4,MATCH("ml.g6.12xlarge",Instancias!$A$2:$A$4,0))&" vCPU · "&INDEX(Instancias!$G$2:$G$4,MATCH("ml.g6.12xlarge",Instancias!$A$2:$A$4,0))&" GiB" -> g6.12xlarge 4× L4 · 96 GB GPU · 48 vCPU · 192 GiB | C14: sem | D14: =IF(COUNTIFS(Testes[Serviço],"Async",Testes[Instância],"ml.g6.12xlarge",Testes[Fracionamento],"Não",Testes[Teste],$C$4)=0,"",IFERROR(AVERAGEIFS(Testes[Throughput processamento (linhas/s)],Testes[Serviço],"Async",Testes[Instância],"ml.g6.12xlarge",Testes[Fracionamento],"Não",Testes[Teste],$C$4),"")) -> 173 | E14: =IF(OR(NOT(ISNUMBER(D14)),NOT(ISNUMBER(D14))),"",IF(ROW()=14,"base",D14/D14-1)) -> base | F14: =IF(COUNTIFS(Testes[Serviço],"Async",Testes[Instância],"ml.g6.12xlarge",Testes[Fracionamento],"Não",Testes[Teste],$C$4)=0,"",IFERROR(AVERAGEIFS(Testes[Tempo total (min)],Testes[Serviço],"Async",Testes[Instância],"ml.g6.12xlarge",Testes[Fracionamento],"Não",Testes[Teste],$C$4)/1440,"")) -> 0.063194444 | G14: =IF(ISNUMBER(D14),24000000/D14/86400,"") -> 1.6056519 | H14: =IF(COUNTIFS(Testes[Serviço],"Async",Testes[Instância],"ml.g6.12xlarge",Testes[Fracionamento],"Não",Testes[Teste],$C$4)=0,"",IFERROR(AVERAGEIFS(Testes[% ok],Testes[Serviço],"Async",Testes[Instância],"ml.g6.12xlarge",Testes[Fracionamento],"Não",Testes[Teste],$C$4),"")) -> 1 | I14: =IF(COUNTIFS(Testes[Serviço],"Async",Testes[Instância],"ml.g6.12xlarge",Testes[Fracionamento],"Não",Testes[Teste],$C$4)=0,"",SUMIFS(Testes[Falhas],Testes[Serviço],"Async",Testes[Instância],"ml.g6.12xlarge",Testes[Fracionamento],"Não",Testes[Teste],$C$4)) -> 0 | J14: =IF(COUNTIFS(Testes[Serviço],"Async",Testes[Instância],"ml.g6.12xlarge",Testes[Fracionamento],"Não",Testes[Teste],$C$4)=0,"",IFERROR(AVERAGEIFS(Testes[Custo (USD)],Testes[Serviço],"Async",Testes[Instância],"ml.g6.12xlarge",Testes[Fracionamento],"Não",Testes[Teste],$C$4),"")) | K14: =IF(COUNTIFS(Testes[Serviço],"Async",Testes[Instância],"ml.g6.12xlarge",Testes[Fracionamento],"Não",Testes[Teste],$C$4)=0,"",IFERROR(AVERAGEIFS(Testes[Custo por 1M linhas (USD)],Testes[Serviço],"Async",Testes[Instância],"ml.g6.12xlarge",Testes[Fracionamento],"Não",Testes[Teste],$C$4),"")) | L14: =IF(ISNUMBER(K14),K14*24,"") | M14: =IF(COUNTIFS(Testes[Serviço],"Async",Testes[Instância],"ml.g6.12xlarge",Testes[Fracionamento],"Não",Testes[Teste],$C$4)=0,"",IFERROR(AVERAGEIFS(Testes[GPU média /GPU],Testes[Serviço],"Async",Testes[Instância],"ml.g6.12xlarge",Testes[Fracionamento],"Não",Testes[Teste],$C$4),"")) -> 0.675 | N14: =IF(COUNTIFS(Testes[Serviço],"Async",Testes[Instância],"ml.g6.12xlarge",Testes[Fracionamento],"Não",Testes[Teste],$C$4)=0,"",IFERROR(AVERAGEIFS(Testes[Mem. GPU média /GPU],Testes[Serviço],"Async",Testes[Instância],"ml.g6.12xlarge",Testes[Fracionamento],"Não",Testes[Teste],$C$4),"")) -> 0.252 | O14: =IF(COUNTIFS(Testes[Serviço],"Async",Testes[Instância],"ml.g6.12xlarge",Testes[Fracionamento],"Não",Testes[Teste],$C$4)=0,"",IFERROR(AVERAGEIFS(Testes[ModelLatency (s)],Testes[Serviço],"Async",Testes[Instância],"ml.g6.12xlarge",Testes[Fracionamento],"Não",Testes[Teste],$C$4),"")) -> 86.9 | P14: =IF(NOT(ISNUMBER(D14)),"não testado",IF(ROW()=14,"referência"&IF(I14>0," · "&I14&" falha(s)",""),IF(E14>=1,TEXT(1+E14,"0")&"× mais rápida",IF(E14>=0.1,"mais rápida ("&TEXT(E14,"+0%")&")",IF(E14<=-0.05,"mais lenta ("&TEXT(E14,"0%")&")","parecida ("&TEXT(E14,"+0%;-0%")&")")))&IF(N(H14)<0.95," · só "&TEXT(H14,"0%")&" ok",IF(I14>0," · "&I14&" falha(s)","")))) -> referência | S14: Async · g6.12xl
B15: ="g6.12xlarge "&INDEX(Instancias!$C$2:$C$4,MATCH("ml.g6.12xlarge",Instancias!$A$2:$A$4,0))&"× "&SUBSTITUTE(INDEX(Instancias!$B$2:$B$4,MATCH("ml.g6.12xlarge",Instancias!$A$2:$A$4,0)),"NVIDIA ","")&" · "&INDEX(Instancias!$E$2:$E$4,MATCH("ml.g6.12xlarge",Instancias!$A$2:$A$4,0))&" GB GPU · "&INDEX(Instancias!$F$2:$F$4,MATCH("ml.g6.12xlarge",Instancias!$A$2:$A$4,0))&" vCPU · "&INDEX(Instancias!$G$2:$G$4,MATCH("ml.g6.12xlarge",Instancias!$A$2:$A$4,0))&" GiB" -> g6.12xlarge 4× L4 · 96 GB GPU · 48 vCPU · 192 GiB | C15: com 0,5 GPU | D15: =IF(COUNTIFS(Testes[Serviço],"Async",Testes[Instância],"ml.g6.12xlarge",Testes[Fracionamento],"Sim",Testes[Teste],$C$4)=0,"",IFERROR(AVERAGEIFS(Testes[Throughput processamento (linhas/s)],Testes[Serviço],"Async",Testes[Instância],"ml.g6.12xlarge",Testes[Fracionamento],"Sim",Testes[Teste],$C$4),"")) -> 80 | E15: =IF(OR(NOT(ISNUMBER(D15)),NOT(ISNUMBER(D14))),"",IF(ROW()=14,"base",D15/D14-1)) -> -0.53757225 | F15: =IF(COUNTIFS(Testes[Serviço],"Async",Testes[Instância],"ml.g6.12xlarge",Testes[Fracionamento],"Sim",Testes[Teste],$C$4)=0,"",IFERROR(AVERAGEIFS(Testes[Tempo total (min)],Testes[Serviço],"Async",Testes[Instância],"ml.g6.12xlarge",Testes[Fracionamento],"Sim",Testes[Teste],$C$4)/1440,"")) -> 0.040972222 | G15: =IF(ISNUMBER(D15),24000000/D15/86400,"") -> 3.4722222 | H15: =IF(COUNTIFS(Testes[Serviço],"Async",Testes[Instância],"ml.g6.12xlarge",Testes[Fracionamento],"Sim",Testes[Teste],$C$4)=0,"",IFERROR(AVERAGEIFS(Testes[% ok],Testes[Serviço],"Async",Testes[Instância],"ml.g6.12xlarge",Testes[Fracionamento],"Sim",Testes[Teste],$C$4),"")) -> 0.3 | I15: =IF(COUNTIFS(Testes[Serviço],"Async",Testes[Instância],"ml.g6.12xlarge",Testes[Fracionamento],"Sim",Testes[Teste],$C$4)=0,"",SUMIFS(Testes[Falhas],Testes[Serviço],"Async",Testes[Instância],"ml.g6.12xlarge",Testes[Fracionamento],"Sim",Testes[Teste],$C$4)) -> 140 | J15: =IF(COUNTIFS(Testes[Serviço],"Async",Testes[Instância],"ml.g6.12xlarge",Testes[Fracionamento],"Sim",Testes[Teste],$C$4)=0,"",IFERROR(AVERAGEIFS(Testes[Custo (USD)],Testes[Serviço],"Async",Testes[Instância],"ml.g6.12xlarge",Testes[Fracionamento],"Sim",Testes[Teste],$C$4),"")) | K15: =IF(COUNTIFS(Testes[Serviço],"Async",Testes[Instância],"ml.g6.12xlarge",Testes[Fracionamento],"Sim",Testes[Teste],$C$4)=0,"",IFERROR(AVERAGEIFS(Testes[Custo por 1M linhas (USD)],Testes[Serviço],"Async",Testes[Instância],"ml.g6.12xlarge",Testes[Fracionamento],"Sim",Testes[Teste],$C$4),"")) | L15: =IF(ISNUMBER(K15),K15*24,"") | M15: =IF(COUNTIFS(Testes[Serviço],"Async",Testes[Instância],"ml.g6.12xlarge",Testes[Fracionamento],"Sim",Testes[Teste],$C$4)=0,"",IFERROR(AVERAGEIFS(Testes[GPU média /GPU],Testes[Serviço],"Async",Testes[Instância],"ml.g6.12xlarge",Testes[Fracionamento],"Sim",Testes[Teste],$C$4),"")) -> 0.975 | N15: =IF(COUNTIFS(Testes[Serviço],"Async",Testes[Instância],"ml.g6.12xlarge",Testes[Fracionamento],"Sim",Testes[Teste],$C$4)=0,"",IFERROR(AVERAGEIFS(Testes[Mem. GPU média /GPU],Testes[Serviço],"Async",Testes[Instância],"ml.g6.12xlarge",Testes[Fracionamento],"Sim",Testes[Teste],$C$4),"")) -> 0.645 | O15: =IF(COUNTIFS(Testes[Serviço],"Async",Testes[Instância],"ml.g6.12xlarge",Testes[Fracionamento],"Sim",Testes[Teste],$C$4)=0,"",IFERROR(AVERAGEIFS(Testes[ModelLatency (s)],Testes[Serviço],"Async",Testes[Instância],"ml.g6.12xlarge",Testes[Fracionamento],"Sim",Testes[Teste],$C$4),"")) -> 285 | P15: =IF(NOT(ISNUMBER(D15)),"não testado",IF(ROW()=14,"referência"&IF(I15>0," · "&I15&" falha(s)",""),IF(E15>=1,TEXT(1+E15,"0")&"× mais rápida",IF(E15>=0.1,"mais rápida ("&TEXT(E15,"+0%")&")",IF(E15<=-0.05,"mais lenta ("&TEXT(E15,"0%")&")","parecida ("&TEXT(E15,"+0%;-0%")&")")))&IF(N(H15)<0.95," · só "&TEXT(H15,"0%")&" ok",IF(I15>0," · "&I15&" falha(s)","")))) -> mais lenta (-54%) · só 30% ok | S15: Async · g6.12xl · frac
B16: ="g5.12xlarge "&INDEX(Instancias!$C$2:$C$4,MATCH("ml.g5.12xlarge",Instancias!$A$2:$A$4,0))&"× "&SUBSTITUTE(INDEX(Instancias!$B$2:$B$4,MATCH("ml.g5.12xlarge",Instancias!$A$2:$A$4,0)),"NVIDIA ","")&" · "&INDEX(Instancias!$E$2:$E$4,MATCH("ml.g5.12xlarge",Instancias!$A$2:$A$4,0))&" GB GPU · "&INDEX(Instancias!$F$2:$F$4,MATCH("ml.g5.12xlarge",Instancias!$A$2:$A$4,0))&" vCPU · "&INDEX(Instancias!$G$2:$G$4,MATCH("ml.g5.12xlarge",Instancias!$A$2:$A$4,0))&" GiB" -> g5.12xlarge 4× A10G · 96 GB GPU · 48 vCPU · 192 GiB | C16: sem | D16: =IF(COUNTIFS(Testes[Serviço],"Async",Testes[Instância],"ml.g5.12xlarge",Testes[Fracionamento],"Não",Testes[Teste],$C$4)=0,"",IFERROR(AVERAGEIFS(Testes[Throughput processamento (linhas/s)],Testes[Serviço],"Async",Testes[Instância],"ml.g5.12xlarge",Testes[Fracionamento],"Não",Testes[Teste],$C$4),"")) | E16: =IF(OR(NOT(ISNUMBER(D16)),NOT(ISNUMBER(D14))),"",IF(ROW()=14,"base",D16/D14-1)) | F16: =IF(COUNTIFS(Testes[Serviço],"Async",Testes[Instância],"ml.g5.12xlarge",Testes[Fracionamento],"Não",Testes[Teste],$C$4)=0,"",IFERROR(AVERAGEIFS(Testes[Tempo total (min)],Testes[Serviço],"Async",Testes[Instância],"ml.g5.12xlarge",Testes[Fracionamento],"Não",Testes[Teste],$C$4)/1440,"")) | G16: =IF(ISNUMBER(D16),24000000/D16/86400,"") | H16: =IF(COUNTIFS(Testes[Serviço],"Async",Testes[Instância],"ml.g5.12xlarge",Testes[Fracionamento],"Não",Testes[Teste],$C$4)=0,"",IFERROR(AVERAGEIFS(Testes[% ok],Testes[Serviço],"Async",Testes[Instância],"ml.g5.12xlarge",Testes[Fracionamento],"Não",Testes[Teste],$C$4),"")) | I16: =IF(COUNTIFS(Testes[Serviço],"Async",Testes[Instância],"ml.g5.12xlarge",Testes[Fracionamento],"Não",Testes[Teste],$C$4)=0,"",SUMIFS(Testes[Falhas],Testes[Serviço],"Async",Testes[Instância],"ml.g5.12xlarge",Testes[Fracionamento],"Não",Testes[Teste],$C$4)) | J16: =IF(COUNTIFS(Testes[Serviço],"Async",Testes[Instância],"ml.g5.12xlarge",Testes[Fracionamento],"Não",Testes[Teste],$C$4)=0,"",IFERROR(AVERAGEIFS(Testes[Custo (USD)],Testes[Serviço],"Async",Testes[Instância],"ml.g5.12xlarge",Testes[Fracionamento],"Não",Testes[Teste],$C$4),"")) | K16: =IF(COUNTIFS(Testes[Serviço],"Async",Testes[Instância],"ml.g5.12xlarge",Testes[Fracionamento],"Não",Testes[Teste],$C$4)=0,"",IFERROR(AVERAGEIFS(Testes[Custo por 1M linhas (USD)],Testes[Serviço],"Async",Testes[Instância],"ml.g5.12xlarge",Testes[Fracionamento],"Não",Testes[Teste],$C$4),"")) | L16: =IF(ISNUMBER(K16),K16*24,"") | M16: =IF(COUNTIFS(Testes[Serviço],"Async",Testes[Instância],"ml.g5.12xlarge",Testes[Fracionamento],"Não",Testes[Teste],$C$4)=0,"",IFERROR(AVERAGEIFS(Testes[GPU média /GPU],Testes[Serviço],"Async",Testes[Instância],"ml.g5.12xlarge",Testes[Fracionamento],"Não",Testes[Teste],$C$4),"")) | N16: =IF(COUNTIFS(Testes[Serviço],"Async",Testes[Instância],"ml.g5.12xlarge",Testes[Fracionamento],"Não",Testes[Teste],$C$4)=0,"",IFERROR(AVERAGEIFS(Testes[Mem. GPU média /GPU],Testes[Serviço],"Async",Testes[Instância],"ml.g5.12xlarge",Testes[Fracionamento],"Não",Testes[Teste],$C$4),"")) | O16: =IF(COUNTIFS(Testes[Serviço],"Async",Testes[Instância],"ml.g5.12xlarge",Testes[Fracionamento],"Não",Testes[Teste],$C$4)=0,"",IFERROR(AVERAGEIFS(Testes[ModelLatency (s)],Testes[Serviço],"Async",Testes[Instância],"ml.g5.12xlarge",Testes[Fracionamento],"Não",Testes[Teste],$C$4),"")) | P16: =IF(NOT(ISNUMBER(D16)),"não testado",IF(ROW()=14,"referência"&IF(I16>0," · "&I16&" falha(s)",""),IF(E16>=1,TEXT(1+E16,"0")&"× mais rápida",IF(E16>=0.1,"mais rápida ("&TEXT(E16,"+0%")&")",IF(E16<=-0.05,"mais lenta ("&TEXT(E16,"0%")&")","parecida ("&TEXT(E16,"+0%;-0%")&")")))&IF(N(H16)<0.95," · só "&TEXT(H16,"0%")&" ok",IF(I16>0," · "&I16&" falha(s)","")))) -> não testado | S16: Async · g5.12xl
B17: ="g5.12xlarge "&INDEX(Instancias!$C$2:$C$4,MATCH("ml.g5.12xlarge",Instancias!$A$2:$A$4,0))&"× "&SUBSTITUTE(INDEX(Instancias!$B$2:$B$4,MATCH("ml.g5.12xlarge",Instancias!$A$2:$A$4,0)),"NVIDIA ","")&" · "&INDEX(Instancias!$E$2:$E$4,MATCH("ml.g5.12xlarge",Instancias!$A$2:$A$4,0))&" GB GPU · "&INDEX(Instancias!$F$2:$F$4,MATCH("ml.g5.12xlarge",Instancias!$A$2:$A$4,0))&" vCPU · "&INDEX(Instancias!$G$2:$G$4,MATCH("ml.g5.12xlarge",Instancias!$A$2:$A$4,0))&" GiB" -> g5.12xlarge 4× A10G · 96 GB GPU · 48 vCPU · 192 GiB | C17: com 0,5 GPU | D17: =IF(COUNTIFS(Testes[Serviço],"Async",Testes[Instância],"ml.g5.12xlarge",Testes[Fracionamento],"Sim",Testes[Teste],$C$4)=0,"",IFERROR(AVERAGEIFS(Testes[Throughput processamento (linhas/s)],Testes[Serviço],"Async",Testes[Instância],"ml.g5.12xlarge",Testes[Fracionamento],"Sim",Testes[Teste],$C$4),"")) | E17: =IF(OR(NOT(ISNUMBER(D17)),NOT(ISNUMBER(D14))),"",IF(ROW()=14,"base",D17/D14-1)) | F17: =IF(COUNTIFS(Testes[Serviço],"Async",Testes[Instância],"ml.g5.12xlarge",Testes[Fracionamento],"Sim",Testes[Teste],$C$4)=0,"",IFERROR(AVERAGEIFS(Testes[Tempo total (min)],Testes[Serviço],"Async",Testes[Instância],"ml.g5.12xlarge",Testes[Fracionamento],"Sim",Testes[Teste],$C$4)/1440,"")) | G17: =IF(ISNUMBER(D17),24000000/D17/86400,"") | H17: =IF(COUNTIFS(Testes[Serviço],"Async",Testes[Instância],"ml.g5.12xlarge",Testes[Fracionamento],"Sim",Testes[Teste],$C$4)=0,"",IFERROR(AVERAGEIFS(Testes[% ok],Testes[Serviço],"Async",Testes[Instância],"ml.g5.12xlarge",Testes[Fracionamento],"Sim",Testes[Teste],$C$4),"")) | I17: =IF(COUNTIFS(Testes[Serviço],"Async",Testes[Instância],"ml.g5.12xlarge",Testes[Fracionamento],"Sim",Testes[Teste],$C$4)=0,"",SUMIFS(Testes[Falhas],Testes[Serviço],"Async",Testes[Instância],"ml.g5.12xlarge",Testes[Fracionamento],"Sim",Testes[Teste],$C$4)) | J17: =IF(COUNTIFS(Testes[Serviço],"Async",Testes[Instância],"ml.g5.12xlarge",Testes[Fracionamento],"Sim",Testes[Teste],$C$4)=0,"",IFERROR(AVERAGEIFS(Testes[Custo (USD)],Testes[Serviço],"Async",Testes[Instância],"ml.g5.12xlarge",Testes[Fracionamento],"Sim",Testes[Teste],$C$4),"")) | K17: =IF(COUNTIFS(Testes[Serviço],"Async",Testes[Instância],"ml.g5.12xlarge",Testes[Fracionamento],"Sim",Testes[Teste],$C$4)=0,"",IFERROR(AVERAGEIFS(Testes[Custo por 1M linhas (USD)],Testes[Serviço],"Async",Testes[Instância],"ml.g5.12xlarge",Testes[Fracionamento],"Sim",Testes[Teste],$C$4),"")) | L17: =IF(ISNUMBER(K17),K17*24,"") | M17: =IF(COUNTIFS(Testes[Serviço],"Async",Testes[Instância],"ml.g5.12xlarge",Testes[Fracionamento],"Sim",Testes[Teste],$C$4)=0,"",IFERROR(AVERAGEIFS(Testes[GPU média /GPU],Testes[Serviço],"Async",Testes[Instância],"ml.g5.12xlarge",Testes[Fracionamento],"Sim",Testes[Teste],$C$4),"")) | N17: =IF(COUNTIFS(Testes[Serviço],"Async",Testes[Instância],"ml.g5.12xlarge",Testes[Fracionamento],"Sim",Testes[Teste],$C$4)=0,"",IFERROR(AVERAGEIFS(Testes[Mem. GPU média /GPU],Testes[Serviço],"Async",Testes[Instância],"ml.g5.12xlarge",Testes[Fracionamento],"Sim",Testes[Teste],$C$4),"")) | O17: =IF(COUNTIFS(Testes[Serviço],"Async",Testes[Instância],"ml.g5.12xlarge",Testes[Fracionamento],"Sim",Testes[Teste],$C$4)=0,"",IFERROR(AVERAGEIFS(Testes[ModelLatency (s)],Testes[Serviço],"Async",Testes[Instância],"ml.g5.12xlarge",Testes[Fracionamento],"Sim",Testes[Teste],$C$4),"")) | P17: =IF(NOT(ISNUMBER(D17)),"não testado",IF(ROW()=14,"referência"&IF(I17>0," · "&I17&" falha(s)",""),IF(E17>=1,TEXT(1+E17,"0")&"× mais rápida",IF(E17>=0.1,"mais rápida ("&TEXT(E17,"+0%")&")",IF(E17<=-0.05,"mais lenta ("&TEXT(E17,"0%")&")","parecida ("&TEXT(E17,"+0%;-0%")&")")))&IF(N(H17)<0.95," · só "&TEXT(H17,"0%")&" ok",IF(I17>0," · "&I17&" falha(s)","")))) -> não testado | S17: Async · g5.12xl · frac
B18: ="p5e.48xlarge "&INDEX(Instancias!$C$2:$C$4,MATCH("ml.p5e.48xlarge",Instancias!$A$2:$A$4,0))&"× "&SUBSTITUTE(INDEX(Instancias!$B$2:$B$4,MATCH("ml.p5e.48xlarge",Instancias!$A$2:$A$4,0)),"NVIDIA ","")&" · "&INDEX(Instancias!$E$2:$E$4,MATCH("ml.p5e.48xlarge",Instancias!$A$2:$A$4,0))&" GB GPU · "&INDEX(Instancias!$F$2:$F$4,MATCH("ml.p5e.48xlarge",Instancias!$A$2:$A$4,0))&" vCPU · "&INDEX(Instancias!$G$2:$G$4,MATCH("ml.p5e.48xlarge",Instancias!$A$2:$A$4,0))&" GiB" -> p5e.48xlarge 8× H200 · 1128 GB GPU · 192 vCPU · 2048 GiB | C18: sem | D18: =IF(COUNTIFS(Testes[Serviço],"Async",Testes[Instância],"ml.p5e.48xlarge",Testes[Fracionamento],"Não",Testes[Teste],$C$4)=0,"",IFERROR(AVERAGEIFS(Testes[Throughput processamento (linhas/s)],Testes[Serviço],"Async",Testes[Instância],"ml.p5e.48xlarge",Testes[Fracionamento],"Não",Testes[Teste],$C$4),"")) -> 2316 | E18: =IF(OR(NOT(ISNUMBER(D18)),NOT(ISNUMBER(D14))),"",IF(ROW()=14,"base",D18/D14-1)) -> 12.387283 | F18: =IF(COUNTIFS(Testes[Serviço],"Async",Testes[Instância],"ml.p5e.48xlarge",Testes[Fracionamento],"Não",Testes[Teste],$C$4)=0,"",IFERROR(AVERAGEIFS(Testes[Tempo total (min)],Testes[Serviço],"Async",Testes[Instância],"ml.p5e.48xlarge",Testes[Fracionamento],"Não",Testes[Teste],$C$4)/1440,"")) -> 0.0049861111 | G18: =IF(ISNUMBER(D18),24000000/D18/86400,"") -> 0.11993859 | H18: =IF(COUNTIFS(Testes[Serviço],"Async",Testes[Instância],"ml.p5e.48xlarge",Testes[Fracionamento],"Não",Testes[Teste],$C$4)=0,"",IFERROR(AVERAGEIFS(Testes[% ok],Testes[Serviço],"Async",Testes[Instância],"ml.p5e.48xlarge",Testes[Fracionamento],"Não",Testes[Teste],$C$4),"")) -> 1 | I18: =IF(COUNTIFS(Testes[Serviço],"Async",Testes[Instância],"ml.p5e.48xlarge",Testes[Fracionamento],"Não",Testes[Teste],$C$4)=0,"",SUMIFS(Testes[Falhas],Testes[Serviço],"Async",Testes[Instância],"ml.p5e.48xlarge",Testes[Fracionamento],"Não",Testes[Teste],$C$4)) -> 0 | J18: =IF(COUNTIFS(Testes[Serviço],"Async",Testes[Instância],"ml.p5e.48xlarge",Testes[Fracionamento],"Não",Testes[Teste],$C$4)=0,"",IFERROR(AVERAGEIFS(Testes[Custo (USD)],Testes[Serviço],"Async",Testes[Instância],"ml.p5e.48xlarge",Testes[Fracionamento],"Não",Testes[Teste],$C$4),"")) | K18: =IF(COUNTIFS(Testes[Serviço],"Async",Testes[Instância],"ml.p5e.48xlarge",Testes[Fracionamento],"Não",Testes[Teste],$C$4)=0,"",IFERROR(AVERAGEIFS(Testes[Custo por 1M linhas (USD)],Testes[Serviço],"Async",Testes[Instância],"ml.p5e.48xlarge",Testes[Fracionamento],"Não",Testes[Teste],$C$4),"")) | L18: =IF(ISNUMBER(K18),K18*24,"") | M18: =IF(COUNTIFS(Testes[Serviço],"Async",Testes[Instância],"ml.p5e.48xlarge",Testes[Fracionamento],"Não",Testes[Teste],$C$4)=0,"",IFERROR(AVERAGEIFS(Testes[GPU média /GPU],Testes[Serviço],"Async",Testes[Instância],"ml.p5e.48xlarge",Testes[Fracionamento],"Não",Testes[Teste],$C$4),"")) -> 0.28375 | N18: =IF(COUNTIFS(Testes[Serviço],"Async",Testes[Instância],"ml.p5e.48xlarge",Testes[Fracionamento],"Não",Testes[Teste],$C$4)=0,"",IFERROR(AVERAGEIFS(Testes[Mem. GPU média /GPU],Testes[Serviço],"Async",Testes[Instância],"ml.p5e.48xlarge",Testes[Fracionamento],"Não",Testes[Teste],$C$4),"")) | O18: =IF(COUNTIFS(Testes[Serviço],"Async",Testes[Instância],"ml.p5e.48xlarge",Testes[Fracionamento],"Não",Testes[Teste],$C$4)=0,"",IFERROR(AVERAGEIFS(Testes[ModelLatency (s)],Testes[Serviço],"Async",Testes[Instância],"ml.p5e.48xlarge",Testes[Fracionamento],"Não",Testes[Teste],$C$4),"")) -> 64.4 | P18: =IF(NOT(ISNUMBER(D18)),"não testado",IF(ROW()=14,"referência"&IF(I18>0," · "&I18&" falha(s)",""),IF(E18>=1,TEXT(1+E18,"0")&"× mais rápida",IF(E18>=0.1,"mais rápida ("&TEXT(E18,"+0%")&")",IF(E18<=-0.05,"mais lenta ("&TEXT(E18,"0%")&")","parecida ("&TEXT(E18,"+0%;-0%")&")")))&IF(N(H18)<0.95," · só "&TEXT(H18,"0%")&" ok",IF(I18>0," · "&I18&" falha(s)","")))) -> 13× mais rápida | S18: Async · p5e.48xl
B21: O que os testes mostraram até agora
B22: Batch: a g5 é ~20% mais rápida que a g6 | C22: 211 contra 176 linhas/s no 1M, com custo quase igual (8,86 contra 8,63 USD). A g6 fica com a GPU no limite; a g5 ainda tem folga.
B24: Na g6, batch e async têm a mesma velocidade | C24: ~175 linhas/s nos dois. A escolha é operacional: custo de deixar o endpoint de pé e o limite de 5 min por requisição no async.
B26: A p5e é ~13× mais rápida que a g6 | C26: 2.316 contra 173 linhas/s no async (24M em 3h14). Foi paga por reserva, então o custo não é comparável direto.
B28: Fracionamento na g6: funcionou, mas não serviu | C28: As 8 réplicas subiram (memória de GPU de 25% para 64% por GPU), mas a velocidade caiu 54% e 70% das requisições do 1M deram timeout. A GPU da g6 já estava cheia.
B30: Falta testar | C30: Batch com fracionamento (teste A/B na g5, que tem folga de GPU), async na g5 e os preços por hora na aba Instancias.
B33: Como ler a tabela
B34: • Linhas por segundo: quanto foi processado por segundo, contando só o que deu certo. Barra maior = mais rápido.
B35: • vs g6 sem fracionamento: compara com a g6 sem fracionamento do mesmo serviço (batch com batch, async com async). Verde = 10% ou mais rápido; vermelho = 5% ou mais lento.
B36: • Tempo e custo p/ 24M: conta simples a partir da velocidade e do custo por 1M do teste escolhido, com 1 instância.
B37: • GPU usada / memória de GPU: média por GPU (100% = GPUs cheias). Quanto mais laranja, mais perto do limite; GPU perto de 100% indica que mais réplicas não ajudam.
B38: • Custo vazio: falta o preço por hora na aba Instancias (o batch usa o custo que você calculou). A p5e foi paga por reserva.
B39: • Barra azul à esquerda = cenário com fracionamento. No Lote 40, a p5e usou requisições de 28.581 linhas (~1,1M linhas), contra ~5.000 nas outras.
B41: Linhas por segundo no teste escolhido

Sheet Leia-me
A1: Testes de GPU · SageMaker
A3: Como a planilha está organizada
A4: Testes: uma linha por teste executado (serviço × instância × fracionamento × tamanho do teste). É a base de tudo. Para incluir um teste novo, adicione uma linha no fim da tabela; as fórmulas se estendem sozinhas.
A5: Instancias: configuração de hardware e preço por hora de cada instância. Os testes buscam daqui o nº de GPUs, vCPUs e o preço.
A6: Resumo: a página para ler. Uma tabela com todas as combinações (serviço × instância × fracionamento) no teste escolhido na célula amarela, as conclusões em texto e um gráfico.
A8: Legenda
A9: Texto azul = valor digitado (veio das notas de Métricas). Texto preto com fundo cinza = fórmula, não editar.
A10: Fundo amarelo = preencha (preço por hora, seleção do comparativo).
A11: Colunas 'Hardware (console)' = como aparece no CloudWatch, somado entre GPUs/vCPUs (g6 e g5 vão até 400%, p5e até 800%). As colunas '/GPU' e '/vCPU' dividem pelo nº de GPUs/vCPUs, para comparar instâncias de tamanhos diferentes.
A13: Custo
A14: Batch: usei o custo que você calculou nas notas (coluna 'Custo informado'). Quando ela estiver vazia, custo = (tempo total − provisionamento) × preço/h do Batch, porque o provisionamento não é cobrado.
A15: Async: custo = tempo total do teste × preço/h de hospedagem (a instância fica de pé o teste todo). Preencha os preços na aba Instancias para o custo aparecer.
... A20: Throughput conta só as requisições/arquivos que deram certo. Compare sempre o mesmo tamanho de teste: o de 1 requisição/arquivo inclui cold start ou provisionamento.

Sheet Instancias
A1: Instância | B1: GPU | C1: Nº GPUs | D1: Memória por GPU (GB) | E1: Memória de GPU total (GB) | F1: vCPUs | G1: RAM (GiB) | H1: Rede | I1: Armazenamento | J1: Preço/h Batch (USD) | K1: Preço/h Async (USD) | L1: Fonte / observação do preço
A2: ml.g6.12xlarge | B2: NVIDIA L4 | C2: 4 | D2: 24 | E2: =C2*D2 -> 96 | F2: 48 | G2: 192 | H2: 40 Gigabit | I2: 4 x 940 GB NVMe SSD | L2: Preencha com o preço on-demand de sa-east-1
A3: ml.g5.12xlarge | B3: NVIDIA A10G | C3: 4 | D3: 24 | E3: =C3*D3 -> 96 | F3: 48 | G3: 192 | H3: 40 Gigabit | I3: 1 x 3800 GB NVMe SSD | L3: Preencha com o preço on-demand de sa-east-1
A4: ml.p5e.48xlarge | B4: NVIDIA H200 | C4: 8 | D4: 141 | E4: =C4*D4 -> 1128 | F4: 192 | G4: 2048 | H4: 3200 Gigabit | I4: 8 x 3840 GB NVMe SSD | L4: Reserva (Training Plan) de US$ 1.290,71, sem preço por hora

Sheet Testes
A1: IDENTIFICAÇÃO | G1: CONFIGURAÇÃO | L1: RESULTADO | X1: HARDWARE (CONSOLE) | AF1: HARDWARE NORMALIZADO | AM1: CUSTO | AQ1: NOTAS
A2: ID | B2: Data | C2: Serviço | D2: Instância | E2: Fracionamento | F2: Teste | G2: GPU | H2: num_gpus por réplica | I2: Réplicas | J2: Concorrência | K2: Linhas por req./arquivo | L2: Itens ok | M2: Itens total | N2: % ok | O2: Linhas processadas | P2: Provisionamento (min) | Q2: Processamento (min) | R2: Tempo total (min) | S2: Throughput processamento (linhas/s) | T2: Throughput total (linhas/s) | U2: Latência média por req. (s) | V2: ModelLatency (s) | W2: Falhas | X2: GPU média % | Y2: GPU pico % | Z2: Mem. GPU média % | AA2: Mem. GPU pico % | AB2: CPU média % | AC2: CPU pico % | AD2: RAM média % | AE2: RAM pico % | AF2: Nº GPUs | AG2: vCPUs | AH2: GPU média /GPU | AI2: GPU pico /GPU | AJ2: Mem. GPU média /GPU | AK2: Mem. GPU pico /GPU | AL2: CPU média /vCPU | AM2: Custo informado (USD) | AN2: Preço/h (USD) | AO2: Custo (USD) | AP2: Custo por 1M linhas (USD) | AQ2: Status | AR2: Observações
A3: B-03 | C3: Batch | D3: ml.g6.12xlarge | E3: Não | F3: 1 req./arquivo | G3: =IFERROR(INDEX(Instancias!$B$2:$B$4,MATCH(D3,Instancias!$A$2:$A$4,0)),"") -> NVIDIA L4 | H3: 1 | I3: 4 | J3: 4 | K3: 5000 | L3: 1 | M3: 1 | N3: =IF(M3="","",L3/M3) -> 1 | O3: 5000 | P3: 8.1 | Q3: 3.23 | R3: 11.35 | S3: 26 | T3: 7 | W3: 0 | X3: 100 | Y3: 50 | Z3: 21.48 | AA3: 20.5 | AB3: 177.93 | AC3: 234 | AD3: 3.74 | AE3: 4.7 | AF3: =IFERROR(INDEX(Instancias!$C$2:$C$4,MATCH(D3,Instancias!$A$2:$A$4,0)),"") -> 4 | AG3: =IFERROR(INDEX(Instancias!$F$2:$F$4,MATCH(D3,Instancias!$A$2:$A$4,0)),"") -> 48 | AH3: =IF(OR(X3="",AF3=""),"",X3/AF3/100) -> 0.25 | AI3: =IF(OR(Y3="",AF3=""),"",Y3/AF3/100) -> 0.125 | AJ3: =IF(OR(Z3="",AF3=""),"",Z3/AF3/100) -> 0.0537 | AK3: =IF(OR(AA3="",AF3=""),"",AA3/AF3/100) -> 0.05125 | AL3: =IF(OR(AB3="",AG3=""),"",AB3/AG3/100) -> 0.03706875 | AM3: 0.3 | AN3: =IFERROR(IF(IF(C3="Batch",IFERROR(INDEX(Instancias!$J$2:$J$4,MATCH(D3,Instancias!$A$2:$A$4,0)),""),IFERROR(INDEX(Instancias!$K$2:$K$4,MATCH(D3,Instancias!$A$2:$A$4,0)),""))=0,"",IF(C3="Batch",IFERROR(INDEX(Instancias!$J$2:$J$4,MATCH(D3,Instancias!$A$2:$A$4,0)),""),IFERROR(INDEX(Instancias!$K$2:$K$4,MATCH(D3,Instancias!$A$2:$A$4,0)),""))),"") | AO3: =IF(AM3<>"",AM3,IF(OR(N(AN3)=0,R3=""),"",IF(C3="Batch",R3-N(P3),R3)/60*AN3)) -> 0.3 | AP3: =IF(OR(AO3="",N(O3)=0),"",AO3/(O3/1000000)) -> 60 | AQ3: OK | AR3: Na nota, a GPU média (100%) está maior que o pico (50%): conferir no CloudWatch
A4: B-05 | C4: Batch | D4: ml.g6.12xlarge | E4: Não | F4: Lote 40 | G4: =IFERROR(INDEX(Instancias!$B$2:$B$4,MATCH(D4,Instancias!$A$2:$A$4,0)),"") -> NVIDIA L4 | H4: 1 | I4: 4 | J4: 8 | K4: 5000 | L4: 40 | M4: 40 | N4: =IF(M4="","",L4/M4) -> 1 | O4: 191486 | P4: 3.33 | Q4: 19.87 | R4: 23.22 | S4: 161 | T4: 137 | W4: 0 | X4: 256 | Y4: 380 | Z4: 38.3 | AA4: 54.7 | AB4: 366 | AC4: 514 | AD4: 7.34 | AE4: 8 | AF4: =IFERROR(INDEX(Instancias!$C$2:$C$4,MATCH(D4,Instancias!$A$2:$A$4,0)),"") -> 4 | AG4: =IFERROR(INDEX(Instancias!$F$2:$F$4,MATCH(D4,Instancias!$A$2:$A$4,0)),"") -> 48 | AH4: =IF(OR(X4="",AF4=""),"",X4/AF4/100) -> 0.64 | AI4: =IF(OR(Y4="",AF4=""),"",Y4/AF4/100) -> 0.95 | AJ4: =IF(OR(Z4="",AF4=""),"",Z4/AF4/100) -> 0.09575 | AK4: =IF(OR(AA4="",AF4=""),"",AA4/AF4/100) -> 0.13675 | AL4: =IF(OR(AB4="",AG4=""),"",AB4/AG4/100) -> 0.07625 | AM4: 1.84 | AN4: =IFERROR(IF(IF(C4="Batch",IFERROR(INDEX(Instancias!$J$2:$J$4,MATCH(D4,Instancias!$A$2:$A$4,0)),""),IFERROR(INDEX(Instancias!$K$2:$K$4,MATCH(D4,Instancias!$A$2:$A$4,0)),""))=0,"",IF(C4="Batch",IFERROR(INDEX(Instancias!$J$2:$J$4,MATCH(D4,Instancias!$A$2:$A$4,0)),""),IFERROR(INDEX(Instancias!$K$2:$K$4,MATCH(D4,Instancias!$A$2:$A$4,0)),""))),"") | AO4: =IF(AM4<>"",AM4,IF(OR(N(AN4)=0,R4=""),"",IF(C4="Batch",R4-N(P4),R4)/60*AN4)) -> 1.84 | AP4: =IF(OR(AO4="",N(O4)=0),"",AO4/(O4/1000000)) -> 9.6090576 | AQ4: OK
A5: B-07 | C5: Batch | D5: ml.g6.12xlarge | E5: Não | F5: 1M | G5: =IFERROR(INDEX(Instancias!$B$2:$B$4,MATCH(D5,Instancias!$A$2:$A$4,0)),"") -> NVIDIA L4 | H5: 1 | I5: 4 | J5: 8 | K5: 5000 | L5: 200 | M5: 200 | N5: =IF(M5="","",L5/M5) -> 1 | O5: 953173 | P5: 8.78 | Q5: 90 | R5: 99 | S5: 176 | T5: 160 | W5: 0 | X5: 383 | Y5: 400 | Z5: 54.8 | AA5: 61.2 | AB5: 531 | AC5: 559 | AD5: 8.1 | AE5: 8.3 | AF5: =IFERROR(INDEX(Instancias!$C$2:$C$4,MATCH(D5,Instancias!$A$2:$A$4,0)),"") -> 4 | AG5: =IFERROR(INDEX(Instancias!$F$2:$F$4,MATCH(D5,Instancias!$A$2:$A$4,0)),"") -> 48 | AH5: =IF(OR(X5="",AF5=""),"",X5/AF5/100) -> 0.9575 | AI5: =IF(OR(Y5="",AF5=""),"",Y5/AF5/100) -> 1 | AJ5: =IF(OR(Z5="",AF5=""),"",Z5/AF5/100) -> 0.137 | AK5: =IF(OR(AA5="",AF5=""),"",AA5/AF5/100) -> 0.153 | AL5: =IF(OR(AB5="",AG5=""),"",AB5/AG5/100) -> 0.110625 | AM5: 8.63 | AN5: =IFERROR(IF(IF(C5="Batch",IFERROR(INDEX(Instancias!$J$2:$J$4,MATCH(D5,Instancias!$A$2:$A$4,0)),""),IFERROR(INDEX(Instancias!$K$2:$K$4,MATCH(D5,Instancias!$A$2:$A$4,0)),""))=0,"",IF(C5="Batch",IFERROR(INDEX(Instancias!$J$2:$J$4,MATCH(D5,Instancias!$A$2:$A$4,0)),""),IFERROR(INDEX(Instancias!$K$2:$K$4,MATCH(D5,Instancias!$A$2:$A$4,0)),""))),"") | AO5: =IF(AM5<>"",AM5,IF(OR(N(AN5)=0,R5=""),"",IF(C5="Batch",R5-N(P5),R5)/60*AN5)) -> 8.63 | AP5: =IF(OR(AO5="",N(O5)=0),"",AO5/(O5/1000000)) -> 9.0539703 | AQ5: OK
A6: B-03 | B6: 14/10/2026 | C6: Batch | D6: ml.g5.12xlarge | E6: Não | F6: 1 req./arquivo | G6: =IFERROR(INDEX(Instancias!$B$2:$B$4,MATCH(D6,Instancias!$A$2:$A$4,0)),"") -> NVIDIA A10G | H6: 1 | I6: 4 | J6: 8 | K6: 5000 | L6: 1 | M6: 1 | N6: =IF(M6="","",L6/M6) -> 1 | O6: 5000 | P6: 10.15 | Q6: 3 | R6: 13.05 | S6: 29 | T6: 6 | W6: 0 | X6: 0 | Y6: 0 | Z6: 13.2 | AA6: 13.2 | AB6: 116 | AC6: 116 | AD6: 3.66 | AE6: 3.66 | AF6: =IFERROR(INDEX(Instancias!$C$2:$C$4,MATCH(D6,Instancias!$A$2:$A$4,0)),"") -> 4 | AG6: =IFERROR(INDEX(Instancias!$F$2:$F$4,MATCH(D6,Instancias!$A$2:$A$4,0)),"") -> 48 | AH6: =IF(OR(X6="",AF6=""),"",X6/AF6/100) -> 0 | AI6: =IF(OR(Y6="",AF6=""),"",Y6/AF6/100) -> 0 | AJ6: =IF(OR(Z6="",AF6=""),"",Z6/AF6/100) -> 0.033 | AK6: =IF(OR(AA6="",AF6=""),"",AA6/AF6/100) -> 0.033 | AL6: =IF(OR(AB6="",AG6=""),"",AB6/AG6/100) -> 0.024166667 | AM6: 0.35 | AN6: =IFERROR(IF(IF(C6="Batch",IFERROR(INDEX(Instancias!$J$2:$J$4,MATCH(D6,Instancias!$A$2:$A$4,0)),""),IFERROR(INDEX(Instancias!$K$2:$K$4,MATCH(D6,Instancias!$A$2:$A$4,0)),""))=0,"",IF(C6="Batch",IFERROR(INDEX(Instancias!$J$2:$J$4,MATCH(D6,Instancias!$A$2:$A$4,0)),""),IFERROR(INDEX(Instancias!$K$2:$K$4,MATCH(D6,Instancias!$A$2:$A$4,0)),""))),"") | AO6: =IF(AM6<>"",AM6,IF(OR(N(AN6)=0,R6=""),"",IF(C6="Batch",R6-N(P6),R6)/60*AN6)) -> 0.35 | AP6: =IF(OR(AO6="",N(O6)=0),"",AO6/(O6/1000000)) -> 70 | AQ6: OK | AR6: Job iulotus-g5-bt-b03-1014-114932
A7: B-05 | B7: 15/10/2026 | C7: Batch | D7: ml.g5.12xlarge | E7: Não | F7: Lote 40 | G7: =IFERROR(INDEX(Instancias!$B$2:$B$4,MATCH(D7,Instancias!$A$2:$A$4,0)),"") -> NVIDIA A10G | H7: 1 | I7: 4 | J7: 8 | K7: 5000 | L7: 40 | M7: 40 | N7: =IF(M7="","",L7/M7) -> 1 | O7: 191486 | P7: 7.78 | Q7: 17 | R7: 25.07 | S7: 185 | T7: 127 | W7: 0 | X7: 246 | Y7: 304 | Z7: 35.8 | AA7: 41.7 | AB7: 400 | AC7: 478 | AD7: 6.51 | AE7: 7.4 | AF7: =IFERROR(INDEX(Instancias!$C$2:$C$4,MATCH(D7,Instancias!$A$2:$A$4,0)),"") -> 4 | AG7: =IFERROR(INDEX(Instancias!$F$2:$F$4,MATCH(D7,Instancias!$A$2:$A$4,0)),"") -> 48 | AH7: =IF(OR(X7="",AF7=""),"",X7/AF7/100) -> 0.615 | AI7: =IF(OR(Y7="",AF7=""),"",Y7/AF7/100) -> 0.76 | AJ7: =IF(OR(Z7="",AF7=""),"",Z7/AF7/100) -> 0.0895 | AK7: =IF(OR(AA7="",AF7=""),"",AA7/AF7/100) -> 0.10425 | AL7: =IF(OR(AB7="",AG7=""),"",AB7/AG7/100) -> 0.083333333 | AM7: 1.99 | AN7: =IFERROR(IF(IF(C7="Batch",IFERROR(INDEX(Instancias!$J$2:$J$4,MATCH(D7,Instancias!$A$2:$A$4,0)),""),IFERROR(INDEX(Instancias!$K$2:$K$4,MATCH(D7,Instancias!$A$2:$A$4,0)),""))=0,"",IF(C7="Batch",IFERROR(INDEX(Instancias!$J$2:$J$4,MATCH(D7,Instancias!$A$2:$A$4,0)),""),IFERROR(INDEX(Instancias!$K$2:$K$4,MATCH(D7,Instancias!$A$2:$A$4,0)),""))),"") | AO7: =IF(AM7<>"",AM7,IF(OR(N(AN7)=0,R7=""),"",IF(C7="Batch",R7-N(P7),R7)/60*AN7)) -> 1.99 | AP7: =IF(OR(AO7="",N(O7)=0),"",AO7/(O7/1000000)) -> 10.392405 | AQ7: OK | AR7: Job iulotus-g5-bt-b05-1015-113747 · mesmos arquivos do lote de 40 da g6
A8: B-07 | B8: 15/10/2026 | C8: Batch | D8: ml.g5.12xlarge | E8: Não | F8: 1M | G8: =IFERROR(INDEX(Instancias!$B$2:$B$4,MATCH(D8,Instancias!$A$2:$A$4,0)),"") -> NVIDIA A10G | H8: 1 | I8: 4 | J8: 8 | K8: 5000 | L8: 200 | M8: 200 | N8: =IF(M8="","",L8/M8) -> 1 | O8: 953173 | P8: 8.82 | Q8: 75 | R8: 83 | S8: 211 | T8: 189 | W8: 0 | X8: 277 | Y8: 340 | Z8: 38.5 | AA8: 47.7 | AB8: 446 | AC8: 492 | AD8: 7.03 | AE8: 7.66 | AF8: =IFERROR(INDEX(Instancias!$C$2:$C$4,MATCH(D8,Instancias!$A$2:$A$4,0)),"") -> 4 | AG8: =IFERROR(INDEX(Instancias!$F$2:$F$4,MATCH(D8,Instancias!$A$2:$A$4,0)),"") -> 48 | AH8: =IF(OR(X8="",AF8=""),"",X8/AF8/100) -> 0.6925 | AI8: =IF(OR(Y8="",AF8=""),"",Y8/AF8/100) -> 0.85 | AJ8: =IF(OR(Z8="",AF8=""),"",Z8/AF8/100) -> 0.09625 | AK8: =IF(OR(AA8="",AF8=""),"",AA8/AF8/100) -> 0.11925 | AL8: =IF(OR(AB8="",AG8=""),"",AB8/AG8/100) -> 0.092916667 | AM8: 8.86 | AN8: =IFERROR(IF(IF(C8="Batch",IFERROR(INDEX(Instancias!$J$2:$J$4,MATCH(D8,Instancias!$A$2:$A$4,0)),""),IFERROR(INDEX(Instancias!$K$2:$K$4,MATCH(D8,Instancias!$A$2:$A$4,0)),""))=0,"",IF(C8="Batch",IFERROR(INDEX(Instancias!$J$2:$J$4,MATCH(D8,Instancias!$A$2:$A$4,0)),""),IFERROR(INDEX(Instancias!$K$2:$K$4,MATCH(D8,Instancias!$A$2:$A$4,0)),""))),"") | AO8: =IF(AM8<>"",AM8,IF(OR(N(AN8)=0,R8=""),"",IF(C8="Batch",R8-N(P8),R8)/60*AN8)) -> 8.86 | AP8: =IF(OR(AO8="",N(O8)=0),"",AO8/(O8/1000000)) -> 9.2952696 | AQ8: OK | AR8: Job iulotus-g5-bt-b07-1015-122331 · mesmos 200 arquivos do 1M da g6
A9: P-03 | B9: 30/09/2026 | C9: Async | D9: ml.g6.12xlarge | E9: Não | F9: 1 req./arquivo | G9: =IFERROR(INDEX(Instancias!$B$2:$B$4,MATCH(D9,Instancias!$A$2:$A$4,0)),"") -> NVIDIA L4 | H9: 1 | I9: 4 | J9: 8 | K9: 5000 | L9: 1 | M9: 1 | N9: =IF(M9="","",L9/M9) -> 1 | O9: 5000 | R9: 11.3 | S9: 7 | T9: 7 | U9: 677.5 | W9: 0 | AF9: =IFERROR(INDEX(Instancias!$C$2:$C$4,MATCH(D9,Instancias!$A$2:$A$4,0)),"") -> 4 | AG9: =IFERROR(INDEX(Instancias!$F$2:$F$4,MATCH(D9,Instancias!$A$2:$A$4,0)),"") -> 48 | AH9: =IF(OR(X9="",AF9=""),"",X9/AF9/100) | AI9: =IF(OR(Y9="",AF9=""),"",Y9/AF9/100) | AJ9: =IF(OR(Z9="",AF9=""),"",Z9/AF9/100) | AK9: =IF(OR(AA9="",AF9=""),"",AA9/AF9/100) | AL9: =IF(OR(AB9="",AG9=""),"",AB9/AG9/100) | AN9: =IFERROR(IF(IF(C9="Batch",IFERROR(INDEX(Instancias!$J$2:$J$4,MATCH(D9,Instancias!$A$2:$A$4,0)),""),IFERROR(INDEX(Instancias!$K$2:$K$4,MATCH(D9,Instancias!$A$2:$A$4,0)),""))=0,"",IF(C9="Batch",IFERROR(INDEX(Instancias!$J$2:$J$4,MATCH(D9,Instancias!$A$2:$A$4,0)),""),IFERROR(INDEX(Instancias!$K$2:$K$4,MATCH(D9,Instancias!$A$2:$A$4,0)),""))),"") | AO9: =IF(AM9<>"",AM9,IF(OR(N(AN9)=0,R9=""),"",IF(C9="Batch",R9-N(P9),R9)/60*AN9)) | AP9: =IF(OR(AO9="",N(O9)=0),"",AO9/(O9/1000000)) | AQ9: OK | AR9: Com cold start (endpoint em 0 instâncias)
A10: P-05 | B10: 30/09/2026 | C10: Async | D10: ml.g6.12xlarge | E10: Não | F10: Lote 40 | G10: =IFERROR(INDEX(Instancias!$B$2:$B$4,MATCH(D10,Instancias!$A$2:$A$4,0)),"") -> NVIDIA L4 | H10: 1 | I10: 4 | J10: 8 | K10: 5000 | L10: 40 | M10: 40 | N10: =IF(M10="","",L10/M10) -> 1 | O10: 191486 | R10: 18.5 | S10: 172 | T10: 172 | U10: 586.6 | V10: 86.5 | W10: 0 | X10: 273 | Y10: 400 | AA10: 155.6 | AB10: 446 | AC10: 590 | AD10: 9.5 | AE10: 9.9 | AF10: =IFERROR(INDEX(Instancias!$C$2:$C$4,MATCH(D10,Instancias!$A$2:$A$4,0)),"") -> 4 | AG10: =IFERROR(INDEX(Instancias!$F$2:$F$4,MATCH(D10,Instancias!$A$2:$A$4,0)),"") -> 48 | AH10: =IF(OR(X10="",AF10=""),"",X10/AF10/100) -> 0.6825 | AI10: =IF(OR(Y10="",AF10=""),"",Y10/AF10/100) -> 1 | AJ10: =IF(OR(Z10="",AF10=""),"",Z10/AF10/100) | AK10: =IF(OR(AA10="",AF10=""),"",AA10/AF10/100) -> 0.389 | AL10: =IF(OR(AB10="",AG10=""),"",AB10/AG10/100) -> 0.092916667 | AN10: =IFERROR(IF(IF(C10="Batch",IFERROR(INDEX(Instancias!$J$2:$J$4,MATCH(D10,Instancias!$A$2:$A$4,0)),""),IFERROR(INDEX(Instancias!$K$2:$K$4,MATCH(D10,Instancias!$A$2:$A$4,0)),""))=0,"",IF(C10="Batch",IFERROR(INDEX(Instancias!$J$2:$J$4,MATCH(D10,Instancias!$A$2:$A$4,0)),""),IFERROR(INDEX(Instancias!$K$2:$K$4,MATCH(D10,Instancias!$A$2:$A$4,0)),""))),"") | AO10: =IF(AM10<>"",AM10,IF(OR(N(AN10)=0,R10=""),"",IF(C10="Batch",R10-N(P10),R10)/60*AN10)) | AP10: =IF(OR(AO10="",N(O10)=0),"",AO10/(O10/1000000)) | AQ10: OK | AR10: Latência inclui a espera na fila
A11: P-07 | B11: 30/09/2026 | C11: Async | D11: ml.g6.12xlarge | E11: Não | F11: 1M | G11: =IFERROR(INDEX(Instancias!$B$2:$B$4,MATCH(D11,Instancias!$A$2:$A$4,0)),"") -> NVIDIA L4 | H11: 1 | I11: 4 | J11: 8 | K11: 5000 | L11: 200 | M11: 200 | N11: =IF(M11="","",L11/M11) -> 1 | O11: 953173 | R11: 91 | S11: 173 | T11: 173 | U11: 2788 | V11: 86.9 | W11: 0 | X11: 270 | Y11: 400 | Z11: 100.8 | AA11: 156.8 | AB11: 451 | AC11: 677 | AD11: 10.1 | AE11: 10.5 | AF11: =IFERROR(INDEX(Instancias!$C$2:$C$4,MATCH(D11,Instancias!$A$2:$A$4,0)),"") -> 4 | AG11: =IFERROR(INDEX(Instancias!$F$2:$F$4,MATCH(D11,Instancias!$A$2:$A$4,0)),"") -> 48 | AH11: =IF(OR(X11="",AF11=""),"",X11/AF11/100) -> 0.675 | AI11: =IF(OR(Y11="",AF11=""),"",Y11/AF11/100) -> 1 | AJ11: =IF(OR(Z11="",AF11=""),"",Z11/AF11/100) -> 0.252 | AK11: =IF(OR(AA11="",AF11=""),"",AA11/AF11/100) -> 0.392 | AL11: =IF(OR(AB11="",AG11=""),"",AB11/AG11/100) -> 0.093958333 | AN11: =IFERROR(IF(IF(C11="Batch",IFERROR(INDEX(Instancias!$J$2:$J$4,MATCH(D11,Instancias!$A$2:$A$4,0)),""),IFERROR(INDEX(Instancias!$K$2:$K$4,MATCH(D11,Instancias!$A$2:$A$4,0)),""))=0,"",IF(C11="Batch",IFERROR(INDEX(Instancias!$J$2:$J$4,MATCH(D11,Instancias!$A$2:$A$4,0)),""),IFERROR(INDEX(Instancias!$K$2:$K$4,MATCH(D11,Instancias!$A$2:$A$4,0)),""))),"") | AO11: =IF(AM11<>"",AM11,IF(OR(N(AN11)=0,R11=""),"",IF(C11="Batch",R11-N(P11),R11)/60*AN11)) | AP11: =IF(OR(AO11="",N(O11)=0),"",AO11/(O11/1000000)) | AQ11: OK
A12: P-07b | B12: 30/09/2026 | C12: Async | D12: ml.g6.12xlarge | E12: Não | F12: Rodada longa | G12: =IFERROR(INDEX(Instancias!$B$2:$B$4,MATCH(D12,Instancias!$A$2:$A$4,0)),"") -> NVIDIA L4 | H12: 1 | I12: 4 | J12: 8 | K12: 5000 | L12: 638 | M12: 640 | N12: =IF(M12="","",L12/M12) -> 0.996875 | O12: 3038167 | R12: 297 | S12: 170 | T12: 170 | U12: 9062 | V12: 87.5 | W12: 2 | X12: 288 | Y12: 400 | AA12: 161.6 | AB12: 461 | AC12: 672 | AD12: 10.1 | AE12: 10.7 | AF12: =IFERROR(INDEX(Instancias!$C$2:$C$4,MATCH(D12,Instancias!$A$2:$A$4,0)),"") -> 4 | AG12: =IFERROR(INDEX(Instancias!$F$2:$F$4,MATCH(D12,Instancias!$A$2:$A$4,0)),"") -> 48 | AH12: =IF(OR(X12="",AF12=""),"",X12/AF12/100) -> 0.72 | AI12: =IF(OR(Y12="",AF12=""),"",Y12/AF12/100) -> 1 | AJ12: =IF(OR(Z12="",AF12=""),"",Z12/AF12/100) | AK12: =IF(OR(AA12="",AF12=""),"",AA12/AF12/100) -> 0.404 | AL12: =IF(OR(AB12="",AG12=""),"",AB12/AG12/100) -> 0.096041667 | AN12: =IFERROR(IF(IF(C12="Batch",IFERROR(INDEX(Instancias!$J$2:$J$4,MATCH(D12,Instancias!$A$2:$A$4,0)),""),IFERROR(INDEX(Instancias!$K$2:$K$4,MATCH(D12,Instancias!$A$2:$A$4,0)),""))=0,"",IF(C12="Batch",IFERROR(INDEX(Instancias!$J$2:$J$4,MATCH(D12,Instancias!$A$2:$A$4,0)),""),IFERROR(INDEX(Instancias!$K$2:$K$4,MATCH(D12,Instancias!$A$2:$A$4,0)),""))),"") | AO12: =IF(AM12<>"",AM12,IF(OR(N(AN12)=0,R12=""),"",IF(C12="Batch",R12-N(P12),R12)/60*AN12)) | AP12: =IF(OR(AO12="",N(O12)=0),"",AO12/(O12/1000000)) | AQ12: Parcial | AR12: 24M não coube no TTL de 6 h; 2 timeouts
A13: P-03 | B13: 15/10/2026 | C13: Async | D13: ml.g6.12xlarge | E13: Sim | F13: 1 req./arquivo | G13: =IFERROR(INDEX(Instancias!$B$2:$B$4,MATCH(D13,Instancias!$A$2:$A$4,0)),"") -> NVIDIA L4 | H13: 0.5 | I13: 8 | J13: 8 | K13: 5000 | L13: 1 | M13: 1 | N13: =IF(M13="","",L13/M13) -> 1 | O13: 5000 | R13: 10.6 | S13: 8 | T13: 8 | U13: 636 | W13: 0 | AF13: =IFERROR(INDEX(Instancias!$C$2:$C$4,MATCH(D13,Instancias!$A$2:$A$4,0)),"") -> 4 | AG13: =IFERROR(INDEX(Instancias!$F$2:$F$4,MATCH(D13,Instancias!$A$2:$A$4,0)),"") -> 48 | AH13: =IF(OR(X13="",AF13=""),"",X13/AF13/100) | AI13: =IF(OR(Y13="",AF13=""),"",Y13/AF13/100) | AJ13: =IF(OR(Z13="",AF13=""),"",Z13/AF13/100) | AK13: =IF(OR(AA13="",AF13=""),"",AA13/AF13/100) | AL13: =IF(OR(AB13="",AG13=""),"",AB13/AG13/100) | AN13: =IFERROR(IF(IF(C13="Batch",IFERROR(INDEX(Instancias!$J$2:$J$4,MATCH(D13,Instancias!$A$2:$A$4,0)),""),IFERROR(INDEX(Instancias!$K$2:$K$4,MATCH(D13,Instancias!$A$2:$A$4,0)),""))=0,"",IF(C13="Batch",IFERROR(INDEX(Instancias!$J$2:$J$4,MATCH(D13,Instancias!$A$2:$A$4,0)),""),IFERROR(INDEX(Instancias!$K$2:$K$4,MATCH(D13,Instancias!$A$2:$A$4,0)),""))),"") | AO13: =IF(AM13<>"",AM13,IF(OR(N(AN13)=0,R13=""),"",IF(C13="Batch",R13-N(P13),R13)/60*AN13)) | AP13: =IF(OR(AO13="",N(O13)=0),"",AO13/(O13/1000000)) | AQ13: OK | AR13: Com cold start
A14: P-05 | B14: 15/10/2026 | C14: Async | D14: ml.g6.12xlarge | E14: Sim | F14: Lote 40 | G14: =IFERROR(INDEX(Instancias!$B$2:$B$4,MATCH(D14,Instancias!$A$2:$A$4,0)),"") -> NVIDIA L4 | H14: 0.5 | I14: 8 | J14: 8 | K14: 5000 | L14: 18 | M14: 40 | N14: =IF(M14="","",L14/M14) -> 0.45 | O14: 87162 | R14: 13 | S14: 111 | T14: 111 | U14: 377 | V14: 249 | W14: 22 | X14: 357 | Y14: 400 | Z14: 210 | AA14: 310.6 | AB14: 772 | AC14: 1099 | AD14: 16.6 | AE14: 17.7 | AF14: =IFERROR(INDEX(Instancias!$C$2:$C$4,MATCH(D14,Instancias!$A$2:$A$4,0)),"") -> 4 | AG14: =IFERROR(INDEX(Instancias!$F$2:$F$4,MATCH(D14,Instancias!$A$2:$A$4,0)),"") -> 48 | AH14: =IF(OR(X14="",AF14=""),"",X14/AF14/100) -> 0.8925 | AI14: =IF(OR(Y14="",AF14=""),"",Y14/AF14/100) -> 1 | AJ14: =IF(OR(Z14="",AF14=""),"",Z14/AF14/100) -> 0.525 | AK14: =IF(OR(AA14="",AF14=""),"",AA14/AF14/100) -> 0.7765 | AL14: =IF(OR(AB14="",AG14=""),"",AB14/AG14/100) -> 0.16083333 | AN14: =IFERROR(IF(IF(C14="Batch",IFERROR(INDEX(Instancias!$J$2:$J$4,MATCH(D14,Instancias!$A$2:$A$4,0)),""),IFERROR(INDEX(Instancias!$K$2:$K$4,MATCH(D14,Instancias!$A$2:$A$4,0)),""))=0,"",IF(C14="Batch",IFERROR(INDEX(Instancias!$J$2:$J$4,MATCH(D14,Instancias!$A$2:$A$4,0)),""),IFERROR(INDEX(Instancias!$K$2:$K$4,MATCH(D14,Instancias!$A$2:$A$4,0)),""))),"") | AO14: =IF(AM14<>"",AM14,IF(OR(N(AN14)=0,R14=""),"",IF(C14="Batch",R14-N(P14),R14)/60*AN14)) | AP14: =IF(OR(AO14="",N(O14)=0),"",AO14/(O14/1000000)) | AQ14: Parcial | AR14: 22 Request timeout (limite de 5 min do Ray)
A15: P-07 | B15: 15/10/2026 | C15: Async | D15: ml.g6.12xlarge | E15: Sim | F15: 1M | G15: =IFERROR(INDEX(Instancias!$B$2:$B$4,MATCH(D15,Instancias!$A$2:$A$4,0)),"") -> NVIDIA L4 | H15: 0.5 | I15: 8 | J15: 8 | K15: 5000 | L15: 60 | M15: 200 | N15: =IF(M15="","",L15/M15) -> 0.3 | O15: 284391 | R15: 59 | S15: 80 | T15: 80 | U15: 1801 | V15: 285 | W15: 140 | X15: 390 | Y15: 400 | Z15: 258 | AA15: 308.9 | AB15: 946 | AC15: 1206 | AD15: 18.8 | AE15: 19.4 | AF15: =IFERROR(INDEX(Instancias!$C$2:$C$4,MATCH(D15,Instancias!$A$2:$A$4,0)),"") -> 4 | AG15: =IFERROR(INDEX(Instancias!$F$2:$F$4,MATCH(D15,Instancias!$A$2:$A$4,0)),"") -> 48 | AH15: =IF(OR(X15="",AF15=""),"",X15/AF15/100) -> 0.975 | AI15: =IF(OR(Y15="",AF15=""),"",Y15/AF15/100) -> 1 | AJ15: =IF(OR(Z15="",AF15=""),"",Z15/AF15/100) -> 0.645 | AK15: =IF(OR(AA15="",AF15=""),"",AA15/AF15/100) -> 0.77225 | AL15: =IF(OR(AB15="",AG15=""),"",AB15/AG15/100) -> 0.19708333 | AN15: =IFERROR(IF(IF(C15="Batch",IFERROR(INDEX(Instancias!$J$2:$J$4,MATCH(D15,Instancias!$A$2:$A$4,0)),""),IFERROR(INDEX(Instancias!$K$2:$K$4,MATCH(D15,Instancias!$A$2:$A$4,0)),""))=0,"",IF(C15="Batch",IFERROR(INDEX(Instancias!$J$2:$J$4,MATCH(D15,Instancias!$A$2:$A$4,0)),""),IFERROR(INDEX(Instancias!$K$2:$K$4,MATCH(D15,Instancias!$A$2:$A$4,0)),""))),"") | AO15: =IF(AM15<>"",AM15,IF(OR(N(AN15)=0,R15=""),"",IF(C15="Batch",R15-N(P15),R15)/60*AN15)) | AP15: =IF(OR(AO15="",N(O15)=0),"",AO15/(O15/1000000)) | AQ15: Parcial | AR15: 140 Request timeout; ModelLatency ~3,3× a da g6 sem fracionamento
A16: P-14 | B16: 15/10/2026 | C16: Async | D16: ml.g6.12xlarge | E16: Sim | F16: 8 req. em voo | G16: =IFERROR(INDEX(Instancias!$B$2:$B$4,MATCH(D16,Instancias!$A$2:$A$4,0)),"") -> NVIDIA L4 | H16: 0.5 | I16: 8 | J16: 8 | K16: 5000 | L16: 20 | M16: 24 | N16: =IF(M16="","",L16/M16) -> 0.83333333 | O16: 97162 | R16: 9.9 | S16: 164 | T16: 164 | U16: 154.3 | W16: 4 | X16: 360 | AB16: 696 | AF16: =IFERROR(INDEX(Instancias!$C$2:$C$4,MATCH(D16,Instancias!$A$2:$A$4,0)),"") -> 4 | AG16: =IFERROR(INDEX(Instancias!$F$2:$F$4,MATCH(D16,Instancias!$A$2:$A$4,0)),"") -> 48 | AH16: =IF(OR(X16="",AF16=""),"",X16/AF16/100) -> 0.9 | AI16: =IF(OR(Y16="",AF16=""),"",Y16/AF16/100) | AJ16: =IF(OR(Z16="",AF16=""),"",Z16/AF16/100) | AK16: =IF(OR(AA16="",AF16=""),"",AA16/AF16/100) | AL16: =IF(OR(AB16="",AG16=""),"",AB16/AG16/100) -> 0.145 | AN16: =IFERROR(IF(IF(C16="Batch",IFERROR(INDEX(Instancias!$J$2:$J$4,MATCH(D16,Instancias!$A$2:$A$4,0)),""),IFERROR(INDEX(Instancias!$K$2:$K$4,MATCH(D16,Instancias!$A$2:$A$4,0)),""))=0,"",IF(C16="Batch",IFERROR(INDEX(Instancias!$J$2:$J$4,MATCH(D16,Instancias!$A$2:$A$4,0)),""),IFERROR(INDEX(Instancias!$K$2:$K$4,MATCH(D16,Instancias!$A$2:$A$4,0)),""))),"") | AO16: =IF(AM16<>"",AM16,IF(OR(N(AN16)=0,R16=""),"",IF(C16="Batch",R16-N(P16),R16)/60*AN16)) | AP16: =IF(OR(AO16="",N(O16)=0),"",AO16/(O16/1000000)) | AQ16: Parcial | AR16: Teste de concorrência: o cliente manda no máximo 8 requisições por vez
